Workbook
Name _dlx2: #REF!
Name _Regression_Int: 1
Name AllApps: #REF!
Name Applications: #REF!
Name IQ_CH: 110000
Name IQ_CQ: 5000
Name IQ_CY: 10000
Name IQ_DAILY: 500000
Name IQ_FH: 100000
Name IQ_FQ: 500
Name IQ_FY: 1000
Name IQ_LTM: 2000
Name IQ_MONTH: 15000
Name IQ_NTM: 6000
Name IQ_WEEK: 50000
Name IQ_YTD: 3000
Name Limit: [1]Inputs!$J$5
Name Print_Area_MI: CAPE2!$A$1547:$P$1558
Name SPWS_WBID: "D59E1A16-371E-4D0F-A93D-481B765CD67C"
Name Summ_Table: [1]Summary!$A$3:$P$127
Name Summ_Table_GD: [1]Summary!$D$3:$D$127
Name Summ_Table_Header: [1]Summary!$A$3:$P$3

Sheet Summary
A1: Group | B1: Ticker | C1: Variable | D1: Starting Date | E1: Frequency
A2: INFLATION | B2: CPILFESL | C2: Consumer Price Index for All Urban Consumers: All Items Less Food and Energy in U.S. City Average | D2: 20821 | E2: Monthly
B3: CPILFESL1YAC | C3: CPILFESL 1-Year Annualized Change (%) | D3: 21186 | E3: Monthly
B4: CPILFESL10YAC | C4: CPILFESL 10-Years Annualized Change (%) | D4: 24473 | E4: Monthly
B5: CPIAUCSL | C5: Consumer Price Index for All Urban Consumers: All Items in U.S. City Average | D5: 17168 | E5: Monthly
B6: CORESTICKM159SFRBATL | C6: Sticky Price Consumer Price Index less Food and Energy | D6: 24838 | E6: Monthly
B7: PCEPI | C7: Personal Consumption Expenditures: Chain-type Price Index | D7: 21551 | E7: Monthly
B8: PCEPILFE | C8: Personal Consumption Expenditures Excluding Food and Energy (Chain-Type Price Index) | D8: 21551 | E8: Monthly
B9: MEDCPIM158SFRBCLE | C9: Median Consumer Price Index | D9: 30317 | E9: Monthly
B10: PPIACO | C10: Producer Price Index by Commodity: All Commodities | D10: 4750 | E10: Monthly
B11: PCUOMFGOMFG | C11: Producer Price Index by Industry: Total Manufacturing Industries | D11: 31017 | E11: Monthly
A12: Production & Business Activity | B12: ISRATIO | C12: Total Business: Inventories to Sales Ratio | D12: 33604 | E12: Monthly
B13: BUSINV | C13: Total Business Inventories (Millions of Dollars) | D13: 33604 | E13: Monthly
B14: TTLCONS | C14: Total Construction Spending: Total Construction in the United States (Millions of Dollars) | D14: 33970 | E14: Monthly
B15: TLMFGCONS | C15: Total Construction Spending: Manufacturing in the United States (Millions od Dollars) | D15: 37257 | E15: Monthly
B16: USSTHPI | C16: All-Transactions House Price Index for the United States | D16: 27395 | E16: Quarterly
B17: PERMIT | C17: New Privately-Owned Housing Units Authorized in Permit-Issuing Places: Total Units (Thousands of Units) | D17: 21916 | E17: Monthly
B18: INDPRO | C18: Industrial Production: Total Index | D18: 6941 | E18: Monthly
B19: TCU | C19: Capacity Utilization: Total Index | D19: 24473 | E19: Monthly
B20: IPMAN | C20: Industrial Production: Manufacturing (NAICS) | D20: 26299 | E20: Monthly
B21: MNFCTRIRSA | C21: Manufacturers: Inventories to Sales Ratio | D21: 33604 | E21: Monthly
B22: WHLSLRIRSA | C22: Merchant Wholesalers: Inventories to Sales Ratio | D22: 33604 | E22: Monthly
B23: USSLIND | C23: Leading Index for the United States (%) | D23: 29952 | E23: Monthly
B24: USPHCI | C24: Coincident Economic Activity Index for the United States | D24: 28856 | E24: Monthly
... B26: GDPC1 | C26: Real Gross Domestic Product (Billions of Chained 2017 Dollars) | D26: 17168 | E26: Quarterly
A27: Financial Conditions | B27: NFCIRISK | C27: Chicago Fed National Financial Conditions Risk Subindex | D27: 25934 | E27: Monthly
B28: NFCICREDIT | C28: Chicago Fed National Financial Conditions Credit Subindex | D28: 25934 | E28: Monthly
B29: NFCILEVERAGE | C29: Chicago Fed National Financial Conditions Leverage Subindex | D29: 25934 | E29: Monthly
A30: Monetary Policies | B30: DFF | C30: Federal Funds Effective Rate (%) | D30: 19906 | E30: Monthly
B31: M1REAL | C31: Real M1 Money Stock (Billions of 1982-84 Dollars) | D31: 21551 | E31: Monthly
B32: M2REAL | C32: Real M2 Money Stock (Billions of 1982-84 Dollars) | D32: 21551 | E32: Monthly
B33: T10YFF | C33: 10-Year Treasury Constant Maturity Minus Federal Funds Rate (%) | D33: 22647 | E33: Monthly
A34: Equity Earning Yield | B34: CAPE | C34: Cyclically Adjusted PE Ratio | D34: 1 | E34: Monthly
A35: Labor | B35: ICSA | C35: Initial Claims (Number of Claims) | D35: 24473 | E35: Monthly
B36: IURSA | C36: Insured Unemployment Rate (%) | D36: 25934 | E36: Monthly
B37: JTSJOL | C37: Job Openings: Total Nonfarm (Thousands) | D37: 36861 | E37: Monthly
B38: PAYEMS | C38: All Employees, Total Nonfarm (Thousands) | D38: 14246 | E38: Monthly
B39: MANEMP | C39: All Employees, Manufacturing (Thousands) | D39: 14246 | E39: Monthly
B40: UNRATE | C40: Unemployment Rate (%) | D40: 17533 | E40: Monthly
A41: National Accounts | B41: IEAXGS | C41: Exports of goods and services (Millions od Dollars) | D41: 36161 | E41: Quarterly
...

Sheet CPILFESL
A1: Link: | B1: Consumer Price Index for All Urban Consumers: All Items Less Food and Energy in U.S. City Average
A3: Date | B3: CPILFESL
A4: 20821 | B4: 100
A5: 20852 | B5: 100.35088
A6: 20880 | B6: 100.70175
A7: 20911 | B7: 101.05263
A8: 20941 | B8: 101.05263
A9: 20972 | B9: 101.40351
A10: 21002 | B10: 101.75439
A11: 21033 | B11: 101.75439
A12: 21064 | B12: 102.10526
A13: 21094 | B13: 102.45614
A14: 21125 | B14: 102.80702
A15: 21155 | B15: 102.80702
... A812: 45413 | B812: 1116.2807

Sheet CPILFESL1YAC
A3: Date | B3: 1-Year Annualized Change
A16: =CPILFESL!A16 -> 21186 | B16: =IFERROR((CPILFESL!B16/CPILFESL!B4)^(1/12)-1, "") -> 0.0023096175
A17: =CPILFESL!A17 -> 21217 | B17: =IFERROR((CPILFESL!B17/CPILFESL!B5)^(1/12)-1, "") -> 0.0023016349
A18: =CPILFESL!A18 -> 21245 | B18: =IFERROR((CPILFESL!B18/CPILFESL!B6)^(1/12)-1, "") -> 0.0022937237
A19: =CPILFESL!A19 -> 21276 | B19: =IFERROR((CPILFESL!B19/CPILFESL!B7)^(1/12)-1, "") -> 0.0020032432
A20: =CPILFESL!A20 -> 21306 | B20: =IFERROR((CPILFESL!B20/CPILFESL!B8)^(1/12)-1, "") -> 0.0020032432
A21: =CPILFESL!A21 -> 21337 | B21: =IFERROR((CPILFESL!B21/CPILFESL!B9)^(1/12)-1, "") -> 0.001996387
A22: =CPILFESL!A22 -> 21367 | B22: =IFERROR((CPILFESL!B22/CPILFESL!B10)^(1/12)-1, "") -> 0.0017079986
A23: =CPILFESL!A23 -> 21398 | B23: =IFERROR((CPILFESL!B23/CPILFESL!B11)^(1/12)-1, "") -> 0.0017079986
A24: =CPILFESL!A24 -> 21429 | B24: =IFERROR((CPILFESL!B24/CPILFESL!B12)^(1/12)-1, "") -> 0.0017021919
A25: =CPILFESL!A25 -> 21459 | B25: =IFERROR((CPILFESL!B25/CPILFESL!B13)^(1/12)-1, "") -> 0.001415866
A26: =CPILFESL!A26 -> 21490 | B26: =IFERROR((CPILFESL!B26/CPILFESL!B14)^(1/12)-1, "") -> 0.001411063
A27: =CPILFESL!A27 -> 21520 | B27: =IFERROR((CPILFESL!B27/CPILFESL!B15)^(1/12)-1, "") -> 0.0016906721
... A812: =CPILFESL!A812 -> 45413 | B812: =IFERROR((CPILFESL!B812/CPILFESL!B800)^(1/12)-1, "") -> 0.002799057

Sheet CPILFESL10YAC
A3: Date | B3: 10-Year Annualized Change
A124: =CPILFESL!A124 -> 24473 | B124: =IFERROR((CPILFESL!B124/CPILFESL!B4)^(1/10)-1, "") -> 0.018399376
A125: =CPILFESL!A125 -> 24504 | B125: =IFERROR((CPILFESL!B125/CPILFESL!B5)^(1/10)-1, "") -> 0.018042728
A126: =CPILFESL!A126 -> 24532 | B126: =IFERROR((CPILFESL!B126/CPILFESL!B6)^(1/10)-1, "") -> 0.01798464
A127: =CPILFESL!A127 -> 24563 | B127: =IFERROR((CPILFESL!B127/CPILFESL!B7)^(1/10)-1, "") -> 0.017926908
A128: =CPILFESL!A128 -> 24593 | B128: =IFERROR((CPILFESL!B128/CPILFESL!B8)^(1/10)-1, "") -> 0.018222433
A129: =CPILFESL!A129 -> 24624 | B129: =IFERROR((CPILFESL!B129/CPILFESL!B9)^(1/10)-1, "") -> 0.018164207
A130: =CPILFESL!A130 -> 24654 | B130: =IFERROR((CPILFESL!B130/CPILFESL!B10)^(1/10)-1, "") -> 0.018106353
A131: =CPILFESL!A131 -> 24685 | B131: =IFERROR((CPILFESL!B131/CPILFESL!B11)^(1/10)-1, "") -> 0.018691638
A132: =CPILFESL!A132 -> 24716 | B132: =IFERROR((CPILFESL!B132/CPILFESL!B12)^(1/10)-1, "") -> 0.018632451
A133: =CPILFESL!A133 -> 24746 | B133: =IFERROR((CPILFESL!B133/CPILFESL!B13)^(1/10)-1, "") -> 0.018573622
A134: =CPILFESL!A134 -> 24777 | B134: =IFERROR((CPILFESL!B134/CPILFESL!B14)^(1/10)-1, "") -> 0.018515172
A135: =CPILFESL!A135 -> 24807 | B135: =IFERROR((CPILFESL!B135/CPILFESL!B15)^(1/10)-1, "") -> 0.019092404
... A812: =CPILFESL!A812 -> 45413 | B812: =IFERROR((CPILFESL!B812/CPILFESL!B692)^(1/10)-1, "") -> 0.029651279

Sheet CPIAUCSL
A1: Link: | B1: Consumer Price Index for All Urban Consumers: All Items in U.S. City Average
A3: Date | B3: CPIAUCSL
A4: 17168 | B4: 100
A5: 17199 | B5: 100.65177
A6: 17227 | B6: 102.42086
A7: 17258 | B7: 102.42086
A8: 17288 | B8: 102.18808
A9: 17319 | B9: 102.7933
A10: 17349 | B10: 103.49162
A11: 17380 | B11: 104.28305
A12: 17411 | B12: 106.33147
A13: 17441 | B13: 106.65736
A14: 17472 | B14: 107.35568
A15: 17502 | B15: 108.9851
... A932: 45413 | B932: 1458.2169

Sheet CORESTICKM159SFRBATL
A1: Link: | B1: Sticky Price Consumer Price Index less Food and Energy
A3: Date | B3: CORESTICKM159SFRBATL
A4: 24838 | B4: 100
A5: 24869 | B5: 100.60129
A6: 24898 | B6: 113.42611
A7: 24929 | B7: 113.80028
A8: 24959 | B8: 111.94964
A9: 24990 | B9: 124.47268
A10: 25020 | B10: 130.15491
A11: 25051 | B11: 135.4544
A12: 25082 | B12: 135.49932
A13: 25112 | B13: 141.91647
A14: 25143 | B14: 147.85305
A15: 25173 | B15: 156.25862
... A680: 45413 | B680: 117.80359

Sheet PCEPI
A1: Link: | B1: Personal Consumption Expenditures: Chain-type Price Index
A3: Date | B3: PCEPI
A4: 21551 | B4: 100
A5: 21582 | B5: 100.09892
A6: 21610 | B6: 100.16486
A7: 21641 | B7: 100.3627
A8: 21671 | B8: 100.41546
A9: 21702 | B9: 100.70562
A10: 21732 | B10: 100.91664
A11: 21763 | B11: 101.06173
A12: 21794 | B12: 101.32551
A13: 21824 | B13: 101.56951
A14: 21855 | B14: 101.63545
A15: 21885 | B15: 101.75415
... A788: 45413 | B788: 811.76471

Sheet PCEPILFE
A1: Link: | B1: Personal Consumption Expenditures Excluding Food and Energy (Chain-Type Price Index)
A3: Date | B3: PCEPILFE
A4: 21551 | B4: 100
A5: 21582 | B5: 100.07741
A6: 21610 | B6: 100.19354
A7: 21641 | B7: 100.44513
A8: 21671 | B8: 100.56771
A9: 21702 | B9: 100.86446
A10: 21732 | B10: 101.10315
A11: 21763 | B11: 101.26443
A12: 21794 | B12: 101.52893
A13: 21824 | B13: 101.70312
A14: 21855 | B14: 101.8902
A15: 21885 | B15: 102.04503
... A788: 45413 | B788: 787.3363

Sheet MEDCPIM158SFRBCLE
A1: Link: | B1: Median Consumer Price Indexed
A3: Date | B3: MEDCPIM158SFRBCLE
A4: 30317 | B4: 100
A5: 30348 | B5: 98.76146
A6: 30376 | B6: 72.0341
A7: 30407 | B7: 96.27892
A8: 30437 | B8: 75.12635
A9: 30468 | B9: 48.68328
A10: 30498 | B10: 73.73555
A11: 30529 | B11: 97.65362
A12: 30560 | B12: 96.47382
A13: 30590 | B13: 93.91889
A14: 30621 | B14: 97.35612
A15: 30651 | B15: 72.32336
... A500: 45413 | B500: 60.15309

Sheet PPIACO
A1: Link: | B1: Producer Price Index by Commodity: All Commodities
A3: Date | B3: PPIACO
A4: 4750 | B4: 100
A5: 4781 | B5: 99.17355
A6: 4809 | B6: 99.17355
A7: 4840 | B7: 99.17355
A8: 4870 | B8: 98.34711
A9: 4901 | B9: 98.34711
A10: 4931 | B10: 99.17355
A11: 4962 | B11: 99.17355
A12: 4993 | B12: 100.82645
A13: 5023 | B13: 100.82645
A14: 5054 | B14: 100
A15: 5084 | B15: 98.34711
... A1340: 45413 | B1340: 2107.1984

Sheet PCUOMFGOMFG
A1: Link: | B1: Producer Price Index by Industry: Total Manufacturing Industries
A3: Date | B3: PCUOMFGOMFG
A4: 31017 | B4: 100
A5: 31048 | B5: 100
A6: 31079 | B6: 100
A7: 31107 | B7: 100
A8: 31138 | B8: 100
A9: 31168 | B9: 100
A10: 31199 | B10: 100
A11: 31229 | B11: 100
A12: 31260 | B12: 100
A13: 31291 | B13: 100
A14: 31321 | B14: 100
A15: 31352 | B15: 100
... A477: 45413 | B477: 248.953

Sheet ISRATIO
A1: Link: | B1: Total Business: Inventories to Sales Ratio
A3: Date | B3: ISRATIO
A4: 33604 | B4: 1.56
A5: 33635 | B5: 1.56
A6: 33664 | B6: 1.53
A7: 33695 | B7: 1.53
A8: 33725 | B8: 1.52
A9: 33756 | B9: 1.52
A10: 33786 | B10: 1.51
A11: 33817 | B11: 1.53
A12: 33848 | B12: 1.51
A13: 33878 | B13: 1.52
A14: 33909 | B14: 1.51
A15: 33939 | B15: 1.51
... A391: 45383 | B391: 1.37

Sheet BUSINV
A1: Link: | B1: Total Business Inventories (Millions of Dollars)
A3: Date | B3: BUSINV
A4: 33604 | B4: 808292
A5: 33635 | B5: 809600
A6: 33664 | B6: 812725
A7: 33695 | B7: 815453
A8: 33725 | B8: 815016
A9: 33756 | B9: 820447
A10: 33786 | B10: 825098
A11: 33817 | B11: 826136
A12: 33848 | B12: 827513
A13: 33878 | B13: 827914
A14: 33909 | B14: 829839
A15: 33939 | B15: 835800
... A391: 45383 | B391: 2545185

Sheet TTLCONS
A1: Link: | B1: Total Construction Spending (Millions of Dollars)
A3: Date | B3: TTLCONS
A4: 33970 | B4: 458080
A5: 34001 | B5: 462967
A6: 34029 | B6: 458399
A7: 34060 | B7: 469425
A8: 34090 | B8: 468998
A9: 34121 | B9: 480247
A10: 34151 | B10: 483571
A11: 34182 | B11: 491494
A12: 34213 | B12: 497297
A13: 34243 | B13: 492823
A14: 34274 | B14: 515934
A15: 34304 | B15: 533150
... A380: 45413 | B380: 2139792

Sheet TLMFGCONS
A1: Link: | B1: Total Construction Spending: Manufacturing in the United States (Millions of Dollars)
A3: Date | B3: TLMFGCONS
A4: 37257 | B4: 28318
A5: 37288 | B5: 25977
A6: 37316 | B6: 24998
A7: 37347 | B7: 24482
A8: 37377 | B8: 23862
A9: 37408 | B9: 23200
A10: 37438 | B10: 22090
A11: 37469 | B11: 20837
A12: 37500 | B12: 20168
A13: 37530 | B13: 20908
A14: 37561 | B14: 21004
A15: 37591 | B15: 20384
... A272: 45413 | B272: 234133

Sheet USSTHPI
A1: Link: | B1: All-Transactions House Price Index for the United States (Quarterly)
A3: Date | B3: USSTHPI
A4: 27395 | B4: 100
A5: 27485 | B5: 101.43501
A6: 27576 | B6: 102.13583
A7: 27668 | B7: 103.88787
A8: 27760 | B8: 104.90572
A9: 27851 | B9: 109.16069
A10: 27942 | B10: 111.02953
A11: 28034 | B11: 112.19756
A12: 28126 | B12: 116.01869
A13: 28216 | B13: 121.32488
A14: 28307 | B14: 124.11146
A15: 28399 | B15: 128.75021
... A200: 45292 | B200: 1108.9271

Sheet PERMIT
A1: Link: | B1: New Privately-Owned Housing Units Authorized in Permit-Issuing Places: Total Units (Thousands of Units)
A3: Date | B3: PERMIT
A4: 21916 | B4: 1092
A5: 21947 | B5: 1088
A6: 21976 | B6: 955
A7: 22007 | B7: 1016
A8: 22037 | B8: 1052
A9: 22068 | B9: 958
A10: 22098 | B10: 999
A11: 22129 | B11: 994
A12: 22160 | B12: 984
A13: 22190 | B13: 972
A14: 22221 | B14: 979
A15: 22251 | B15: 951
... A776: 45413 | B776: 1399

Sheet INDPRO
A1: Link: | B1: Industrial Production: Total Index
A3: Date | B3: INDPRO
A4: 6941 | B4: 100
A5: 6972 | B5: 95.58104
A6: 7000 | B6: 92.81868
A7: 7031 | B7: 94.47527
A8: 7061 | B8: 95.02816
A9: 7092 | B9: 101.10577
A10: 7122 | B10: 107.18338
A11: 7153 | B11: 108.83997
A12: 7184 | B12: 106.63049
A13: 7214 | B13: 105.52473
A14: 7245 | B14: 103.86813
A15: 7275 | B15: 105.52473
... A1268: 45413 | B1268: 2119.39

Sheet TCU
A1: Link: | B1: Capacity Utilization: Total Index
A3: Date | B3: TCU
A4: 24473 | B4: 100
A5: 24504 | B5: 98.41683
A6: 24532 | B6: 97.41952
A7: 24563 | B7: 97.89541
A8: 24593 | B8: 96.60634
A9: 24624 | B9: 96.163
A10: 24654 | B10: 95.51752
A11: 24685 | B11: 96.91655
A12: 24716 | B12: 96.33293
A13: 24746 | B13: 96.69125
A14: 24777 | B14: 97.6456
A15: 24807 | B15: 98.26771
... A692: 45413 | B692: 87.44426

Sheet IPMAN
A1: Link: | B1: Industrial Production: Manufacturing (NAICS)
A3: Date | B3: IPMAN
A4: 26299 | B4: 100
A5: 26330 | B5: 100.76385
A6: 26359 | B6: 101.43865
A7: 26390 | B7: 102.58791
A8: 26420 | B8: 102.77518
A9: 26451 | B9: 103.08156
A10: 26481 | B10: 103.06764
A11: 26512 | B11: 104.43311
A12: 26543 | B12: 105.18054
A13: 26573 | B13: 106.75415
A14: 26604 | B14: 108.1391
A15: 26634 | B15: 109.69518
... A632: 45413 | B632: 278.3601

Sheet MNFCTRIRSA
A1: Link: | B1: Manufacturers: Inventories to Sales Ratio
A3: Date | B3: MNFCTRIRSA
A4: 33604 | B4: 1.66
A5: 33635 | B5: 1.65
A6: 33664 | B6: 1.58
A7: 33695 | B7: 1.57
A8: 33725 | B8: 1.55
A9: 33756 | B9: 1.53
A10: 33786 | B10: 1.54
A11: 33817 | B11: 1.56
A12: 33848 | B12: 1.55
A13: 33878 | B13: 1.56
A14: 33909 | B14: 1.53
A15: 33939 | B15: 1.53
... A391: 45383 | B391: 1.45

Sheet WHLSLRIRSA
A1: Link: | B1: Merchant Wholesalers: Inventories to Sales Ratio
A3: Date | B3: WHLSLRIRSA
A4: 33604 | B4: 1.32
A5: 33635 | B5: 1.31
A6: 33664 | B6: 1.31
A7: 33695 | B7: 1.31
A8: 33725 | B8: 1.31
A9: 33756 | B9: 1.32
A10: 33786 | B10: 1.29
A11: 33817 | B11: 1.31
A12: 33848 | B12: 1.3
A13: 33878 | B13: 1.3
A14: 33909 | B14: 1.3
A15: 33939 | B15: 1.33
... A391: 45383 | B391: 1.35

Sheet USSLIND
A1: Link: | B1: Leading Index for the United States (%)
A3: Date | B3: USSLIND
A4: 29952 | B4: -0.89
A5: 29983 | B5: -0.38
A6: 30011 | B6: -0.15
A7: 30042 | B7: -0.11
A8: 30072 | B8: -0.05
A9: 30103 | B9: -0.03
A10: 30133 | B10: -0.06
A11: 30164 | B11: -0.23
A12: 30195 | B12: -0.2
A13: 30225 | B13: 0.01
A14: 30256 | B14: 0.48
A15: 30286 | B15: 0.94
... A461: 43862 | B461: 1.72

Sheet USPHCI
A1: Link: | B1: Coincident Economic Activity Index for the United States
A3: Date | B3: USPHCI
A4: 28856 | B4: 100
A5: 28887 | B5: 100.3288
A6: 28915 | B6: 100.83297
A7: 28946 | B7: 100.98641
A8: 28976 | B8: 101.46865
A9: 29007 | B9: 101.75362
A10: 29037 | B10: 102.01666
A11: 29068 | B11: 102.10434
A12: 29099 | B12: 102.32354
A13: 29129 | B13: 102.52082
A14: 29160 | B14: 102.76195
A15: 29190 | B15: 102.89347
... A548: 45413 | B548: 315.73871

Sheet JHGDPBRINDX
A1: Link: | B1: GDP-Based Recession Indicator Index (%,Quarterly)
A3: Date | B3: JHGDPBRINDX
A4: 24746 | B4: 3.8348
A5: 24838 | B5: 1.7614
A6: 24929 | B6: 1.2127
A7: 25020 | B7: 2.3009
A8: 25112 | B8: 6.3338
A9: 25204 | B9: 12.9501
A10: 25294 | B10: 20.4605
A11: 25385 | B11: 45.7028
A12: 25477 | B12: 89.2282
A13: 25569 | B13: 97.60567
A14: 25659 | B14: 91.58425
A15: 25750 | B15: 94.99551
... A228: 45200 | B228: 2

Sheet GDPC1
A1: Link: | B1: Real Gross Domestic Product, Billions of Chained 2017 Dollars (Quarterly)
A3: Date | B3: GDPC1
A4: 17168 | B4: 2182.681
A5: 17258 | B5: 2176.892
A6: 17349 | B6: 2172.432
A7: 17441 | B7: 2206.452
A8: 17533 | B8: 2239.682
A9: 17624 | B9: 2276.69
A10: 17715 | B10: 2289.77
A11: 17807 | B11: 2292.364
A12: 17899 | B12: 2260.807
A13: 17989 | B13: 2253.128
A14: 18080 | B14: 2276.424
A15: 18172 | B15: 2257.352
... A312: 45292 | B312: 22758.752

Sheet NFCIRISK
A1: Link: | B1: Chicago Fed National Financial Conditions Risk Subindex
A3: Date | B3: NFCIRISK
A4: 25934 | B4: 0.726735
A5: 25965 | B5: 0.905425
A6: 25993 | B6: 1.0690775
A7: 26024 | B7: 1.421022
A8: 26054 | B8: 1.7278425
A9: 26085 | B9: 1.4202575
A10: 26115 | B10: 1.19168
A11: 26146 | B11: 1.98678
A12: 26177 | B12: 2.4685175
A13: 26207 | B13: 1.925338
A14: 26238 | B14: 1.4772425
A15: 26268 | B15: 1.524332
... A644: 45413 | B644: -0.583542
A645: 45444 | B645: =NA() -> #N/A

Sheet NFCICREDIT
A1: Link: | B1: Chicago Fed National Financial Conditions Credit Subindex
A3: Date | B3: NFCICREDIT
A4: 25934 | B4: -1.133835
A5: 25965 | B5: -1.163
A6: 25993 | B6: -1.2430525
A7: 26024 | B7: -1.429476
A8: 26054 | B8: -1.6713475
A9: 26085 | B9: -1.8363925
A10: 26115 | B10: -1.869844
A11: 26146 | B11: -1.7267525
A12: 26177 | B12: -1.5101625
A13: 26207 | B13: -1.314048
A14: 26238 | B14: -1.2596525
A15: 26268 | B15: -1.370172
... A644: 45413 | B644: -0.059984
A645: 45444 | B645: =NA() -> #N/A

Sheet NFCILEVERAGE
A1: Link: | B1: Chicago Fed National Financial Conditions Leverage Subindex
A3: Date | B3: NFCILEVERAGE
A4: 25934 | B4: -1.9392625
A5: 25965 | B5: -2.03208
A6: 25993 | B6: -2.0838725
A7: 26024 | B7: -2.064836
A8: 26054 | B8: -1.9745675
A9: 26085 | B9: -1.8626275
A10: 26115 | B10: -1.73583
A11: 26146 | B11: -1.634975
A12: 26177 | B12: -1.587245
A13: 26207 | B13: -1.595868
A14: 26238 | B14: -1.6653825
A15: 26268 | B15: -1.749604
... A644: 45413 | B644: -0.093876
A645: 45444 | B645: =NA() -> #N/A

Sheet DFF
A1: Link: | B1: Federal Funds Effective Rate (%)
A3: Date | B3: DFF
A4: 19906 | B4: 0.79935484
A5: 19937 | B5: 1.2206452
A6: 19968 | B6: 1.0666667
A7: 19998 | B7: 0.84870968
A8: 20029 | B8: 0.83366667
A9: 20059 | B9: 1.2777419
A10: 20090 | B10: 1.3912903
A11: 20121 | B11: 1.2917857
A12: 20149 | B12: 1.3467742
A13: 20180 | B13: 1.4276667
A14: 20210 | B14: 1.4332258
A15: 20241 | B15: 1.6446667
... A843: 45444 | B843: 5.33

Sheet M1REAL
A1: Link: | B1: Real M1 Money Stock (Billions of 1982-84 Dollars)
A3: Date | B3: M1REAL
A4: 21551 | B4: 478.8
A5: 21582 | B5: 480.7
A6: 21610 | B6: 482.2
A7: 21641 | B7: 482.1
A8: 21671 | B8: 484.5
A9: 21702 | B9: 485.1
A10: 21732 | B10: 486.1
A11: 21763 | B11: 486.3
A12: 21794 | B12: 482.1
A13: 21824 | B13: 478.7
A14: 21855 | B14: 478.4
A15: 21885 | B15: 475.7
... A788: 45413 | B788: 5758.3

Sheet M2REAL
A1: Link: | B1: Real M2 Money Stock (Billions of 1982-84 Dollars)
A3: Date | B3: M2REAL
A4: 21551 | B4: 987.9
A5: 21582 | B5: 992.1
A6: 21610 | B6: 998.3
A7: 21641 | B7: 1001
A8: 21671 | B8: 1006.2
A9: 21702 | B9: 1010.3
A10: 21732 | B10: 1012.7
A11: 21763 | B11: 1015.8
A12: 21794 | B12: 1014.4
A13: 21824 | B13: 1010.2
A14: 21855 | B14: 1012.3
A15: 21885 | B15: 1012.6
... A788: 45413 | B788: 6692.8

Sheet T10YFF
A1: Link: | B1: 10-Year Treasury Constant Maturity Minus Federal Funds Rate (Percent)
A3: Date | B3: T10YFF
A4: 22647 | B4: 2.0604545
A5: 22678 | B5: 1.6505556
A6: 22706 | B6: 1.0781818
A7: 22737 | B7: 1.043
A8: 22767 | B8: 1.4418182
A9: 22798 | B9: 1.2066667
A10: 22828 | B10: 1.3238095
A11: 22859 | B11: 1.03
A12: 22890 | B12: 1.0842105
A13: 22920 | B13: 1.0154545
A14: 22951 | B14: 0.97368421
A15: 22981 | B15: 0.94894737
... A753: 45444 | B753: -1.0247368
A754: 45474 | B754: =NA() -> #N/A

Sheet CAPE
A1: Link: | B1: https://shillerdata.com/
A3: Date | B3: CAPE
A4: 1 | B4: 18.674275
A5: 32 | B5: 18.703797
A6: 61 | B6: 18.775793
A7: 92 | B7: 18.936402
A8: 122 | B8: 18.403197
A9: 153 | B9: 17.992712
A10: 183 | B10: 17.689545
A11: 214 | B11: 18.069615
A12: 245 | B12: 17.341874
A13: 275 | B13: 18.102399
A14: 306 | B14: 19.419585
A15: 336 | B15: 20.744051
... A1497: 45444 | B1497: 34.075523

Sheet CAPE2
D1: Link: | P1: https://shillerdata.com/
A2: Stock Market Data Used in "Irrational Exuberance" Princeton University Press, 2000, 2005, 2015, updated | P2: Cyclically | R2: Cyclically
A3: Robert J. Shiller | P3: Adjusted | R3: Adjusted
P4: Price | R4: Total Return Price
H5: Consumer | M5: Real | O5: Real | P5: Earnings | R5: Earnings | U5: Monthly | V5: Real
E6: S&P | H6: Price | J6: Long | M6: Total | O6: TR | P6: Ratio | R6: Ratio | T6: Excess | U6: Total | V6: Total | W6: 10 Year | X6: 10 Year | Y6: Real 10 Year
E7: Comp. | F7: Dividend | G7: Earnings | H7: Index | I7: Date | J7: Interest | K7: Real | L7: Real | M7: Return | N7: Real | O7: Scaled | P7: P/E10 or | R7: TR P/E10 or | T7: CAPE | U7: Bond | V7: Bond | W7: Annualized Stock | X7: Annualized Bonds | Y7: Excess Annualized
A9: Date-wrong | B9: Year | C9: Month | D9: Date | E9: P | F9: D | G9: E | H9: CPI | I9: Fraction | J9: Rate GS10 | K9: Price | L9: Dividend | M9: Price | N9: Earnings | O9: Earnings | P9: CAPE | R9: TR CAPE | T9: Yield | U9: Returns | V9: Returns | W9: Real Return | X9: Real Return | Y9: Returns
A10: 1871.01 | B10: =VALUE(LEFT(A10, 4)) -> 1871 | C10: 1 | D10: =DATE(B10, VALUE(C10), 1) -> 683371 | E10: 4.44 | F10: 0.26 | G10: 0.4 | H10: 12.464061 | I10: =1871+1/24 -> 1871.0417 | J10: 5.32 | K10: =E10*$H$1851/H10 -> 112.01826 | L10: =F10*$H$1851/H10 -> 6.5596276 | M10: =K10 -> 112.01826 | N10: =G10*$H$1851/H10 -> 10.091735 | O10: =N10*(M10/K10) -> 10.091735 | P10: NA | R10: NA | U10: =((J10/J11+J10/1200+((1+J11/1200)^(-119))*(1-J10/J11))) -> 1.0041769 | V10: 1 | W10: =(($M130/$M10)^(1/10)-1) -> 0.13060945 | X10: =(($V130/$V10)^(1/10)-1) -> 0.092503676 | Y10: =W10-X10 -> 0.03810577
A11: 1871.02 | B11: =VALUE(LEFT(A11, 4)) -> 1871 | C11: 2 | D11: =DATE(B11, VALUE(C11), 1) -> 683402 | E11: 4.5 | F11: 0.26 | G11: 0.4 | H11: 12.844641 | I11: =I10+1/12 -> 1871.125 | J11: =J10*11/12+J22*1/12 -> 5.3233333 | K11: =E11*$H$1851/H11 -> 110.16812 | L11: =F11*$H$1851/H11 -> 6.3652692 | M11: =M10*((K11+(L11/12))/K10) -> 110.69856 | N11: =G11*$H$1851/H11 -> 9.7927219 | O11: =N11*(M11/K11) -> 9.839872 | P11: NA | R11: NA | U11: =((J11/J12+J11/1200+((1+J12/1200)^(-119))*(1-J11/J12))) -> 1.0041798 | V11: =V10*U10*H10/H11 -> 0.97442369 | W11: =(($M131/$M11)^(1/10)-1) -> 0.13085848 | X11: =(($V131/$V11)^(1/10)-1) -> 0.094634634 | Y11: =W11-X11 -> 0.036223847
A12: 1871.03 | B12: =VALUE(LEFT(A12, 4)) -> 1871 | C12: 3 | D12: =DATE(B12, VALUE(C12), 1) -> 683430 | E12: 4.61 | F12: 0.26 | G12: 0.4 | H12: 13.034972 | I12: =I11+1/12 -> 1871.2083 | J12: =J10*10/12+J22*2/12 -> 5.3266667 | K12: =E12*$H$1851/H12 -> 111.21317 | L12: =F12*$H$1851/H12 -> 6.2723265 | M12: =M11*((K12+(L12/12))/K11) -> 112.27386 | N12: =G12*$H$1851/H12 -> 9.6497331 | O12: =N12*(M12/K12) -> 9.7417662 | P12: NA | R12: NA | U12: =((J12/J13+J12/1200+((1+J13/1200)^(-119))*(1-J12/J13))) -> 1.0041826 | V12: =V11*U11*H11/H12 -> 0.96420899 | W12: =(($M132/$M12)^(1/10)-1) -> 0.13095087 | X12: =(($V132/$V12)^(1/10)-1) -> 0.096185996 | Y12: =W12-X12 -> 0.034764877
A13: 1871.04 | B13: =VALUE(LEFT(A13, 4)) -> 1871 | C13: 4 | D13: =DATE(B13, VALUE(C13), 1) -> 683461 | E13: 4.74 | F13: 0.26 | G13: 0.4 | H13: 12.559226 | I13: =I12+1/12 -> 1871.2917 | J13: =J10*9/12+J22*3/12 -> 5.33 | K13: =E13*$H$1851/H13 -> 118.68091 | L13: =F13*$H$1851/H13 -> 6.5099232 | M13: =M12*((K13+(L13/12))/K12) -> 120.36048 | N13: =G13*$H$1851/H13 -> 10.015267 | O13: =N13*(M13/K13) -> 10.157002 | P13: NA | R13: NA | U13: =((J13/J14+J13/1200+((1+J14/1200)^(-119))*(1-J13/J14))) -> 1.0041854 | V13: =V12*U12*H12/H13 -> 1.004919 | W13: =(($M133/$M13)^(1/10)-1) -> 0.12205604 | X13: =(($V133/$V13)^(1/10)-1) -> 0.090971906 | Y13: =W13-X13 -> 0.031084131
A14: 1871.05 | B14: =VALUE(LEFT(A14, 4)) -> 1871 | C14: 5 | D14: =DATE(B14, VALUE(C14), 1) -> 683491 | E14: 4.86 | F14: 0.26 | G14: 0.4 | H14: 12.273812 | I14: =I13+1/12 -> 1871.375 | J14: =J10*8/12+J22*4/12 -> 5.3333333 | K14: =E14*$H$1851/H14 -> 124.51516 | L14: =F14*$H$1851/H14 -> 6.6613048 | M14: =M13*((K14+(L14/12))/K13) -> 126.84026 | N14: =G14*$H$1851/H14 -> 10.248161 | O14: =N14*(M14/K14) -> 10.439528 | P14: NA | R14: NA | U14: =((J14/J15+J14/1200+((1+J15/1200)^(-119))*(1-J14/J15))) -> 1.0041882 | V14: =V13*U13*H13/H14 -> 1.0325911 | W14: =(($M134/$M14)^(1/10)-1) -> 0.1226381 | X14: =(($V134/$V14)^(1/10)-1) -> 0.089488437 | Y14: =W14-X14 -> 0.033149662
A15: 1871.06 | B15: =VALUE(LEFT(A15, 4)) -> 1871 | C15: 6 | D15: =DATE(B15, VALUE(C15), 1) -> 683522 | E15: 4.82 | F15: 0.26 | G15: 0.4 | H15: 12.083481 | I15: =I14+1/12 -> 1871.4583 | J15: =J10*7/12+J22*5/12 -> 5.3366667 | K15: =E15*$H$1851/H15 -> 125.43548 | L15: =F15*$H$1851/H15 -> 6.766229 | M15: =M14*((K15+(L15/12))/K14) -> 128.35215 | N15: =G15*$H$1851/H15 -> 10.409583 | O15: =N15*(M15/K15) -> 10.65163 | P15: NA | R15: NA | U15: =((J15/J16+J15/1200+((1+J16/1200)^(-119))*(1-J15/J16))) -> 1.004191 | V15: =V14*U14*H14/H15 -> 1.0532486 | W15: =(($M135/$M15)^(1/10)-1) -> 0.1230928 | X15: =(($V135/$V15)^(1/10)-1) -> 0.087724911 | Y15: =W15-X15 -> 0.035367889
A16: 1871.07 | B16: =VALUE(LEFT(A16, 4)) -> 1871 | C16: 7 | D16: =DATE(B16, VALUE(C16), 1) -> 683552 | E16: 4.73 | F16: 0.26 | G16: 0.4 | H16: 12.083481 | I16: =I15+1/12 -> 1871.5417 | J16: =J10*6/12+J22*6/12 -> 5.34 | K16: =E16*$H$1851/H16 -> 123.09332 | L16: =F16*$H$1851/H16 -> 6.766229 | M16: =M15*((K16+(L16/12))/K15) -> 126.53249 | N16: =G16*$H$1851/H16 -> 10.409583 | O16: =N16*(M16/K16) -> 10.700422 | P16: NA | R16: NA | U16: =((J16/J17+J16/1200+((1+J17/1200)^(-119))*(1-J16/J17))) -> 1.0041938 | V16: =V15*U15*H15/H16 -> 1.0576628 | W16: =(($M136/$M16)^(1/10)-1) -> 0.12002182 | X16: =(($V136/$V16)^(1/10)-1) -> 0.086580856 | Y16: =W16-X16 -> 0.03344096
A17: 1871.08 | B17: =VALUE(LEFT(A17, 4)) -> 1871 | C17: 8 | D17: =DATE(B17, VALUE(C17), 1) -> 683583 | E17: 4.79 | F17: 0.26 | G17: 0.4 | H17: 11.893231 | I17: =I16+1/12 -> 1871.625 | J17: =J10*5/12+J22*7/12 -> 5.3433333 | K17: =E17*$H$1851/H17 -> 126.64879 | L17: =F17*$H$1851/H17 -> 6.8744647 | M17: =M16*((K17+(L17/12))/K16) -> 130.77618 | N17: =G17*$H$1851/H17 -> 10.5761 | O17: =N17*(M17/K17) -> 10.920767 | P17: NA | R17: NA | U17: =((J17/J18+J17/1200+((1+J18/1200)^(-119))*(1-J17/J18))) -> 1.0041967 | V17: =V16*U16*H16/H17 -> 1.0790883 | W17: =(($M137/$M17)^(1/10)-1) -> 0.11193301 | X17: =(($V137/$V17)^(1/10)-1) -> 0.082668611 | Y17: =W17-X17 -> 0.029264399
A18: 1871.09 | B18: =VALUE(LEFT(A18, 4)) -> 1871 | C18: 9 | D18: =DATE(B18, VALUE(C18), 1) -> 683614 | E18: 4.84 | F18: 0.26 | G18: 0.4 | H18: 12.178646 | I18: =I17+1/12 -> 1871.7083 | J18: =J10*4/12+J22*8/12 -> 5.3466667 | K18: =E18*$H$1851/H18 -> 124.97172 | L18: =F18*$H$1851/H18 -> 6.713357 | M18: =M17*((K18+(L18/12))/K17) -> 129.62213 | N18: =G18*$H$1851/H18 -> 10.328242 | O18: =N18*(M18/K18) -> 10.712573 | P18: NA | R18: NA | U18: =((J18/J19+J18/1200+((1+J19/1200)^(-119))*(1-J18/J19))) -> 1.0041995 | V18: =V17*U17*H17/H18 -> 1.0582215 | W18: =(($M138/$M18)^(1/10)-1) -> 0.11002821 | X18: =(($V138/$V18)^(1/10)-1) -> 0.081047905 | Y18: =W18-X18 -> 0.028980301
A19: 1871.1 | B19: =VALUE(LEFT(A19, 4)) -> 1871 | C19: 10 | D19: =DATE(B19, VALUE(C19), 1) -> 683644 | E19: 4.59 | F19: 0.26 | G19: 0.4 | H19: 12.368896 | I19: =I18+1/12 -> 1871.7917 | J19: =J10*3/12+J22*9/12 -> 5.35 | K19: =E19*$H$1851/H19 -> 116.69363 | L19: =F19*$H$1851/H19 -> 6.6100969 | M19: =M18*((K19+(L19/12))/K18) -> 121.60734 | N19: =G19*$H$1851/H19 -> 10.16938 | O19: =N19*(M19/K19) -> 10.59759 | P19: NA | R19: NA | U19: =((J19/J20+J19/1200+((1+J20/1200)^(-119))*(1-J19/J20))) -> 1.0042023 | V19: =V18*U18*H18/H19 -> 1.0463203 | W19: =(($M139/$M19)^(1/10)-1) -> 0.11476526 | X19: =(($V139/$V19)^(1/10)-1) -> 0.081652652 | Y19: =W19-X19 -> 0.033112606
A20: 1871.11 | B20: =VALUE(LEFT(A20, 4)) -> 1871 | C20: 11 | D20: =DATE(B20, VALUE(C20), 1) -> 683675 | E20: 4.64 | F20: 0.26 | G20: 0.4 | H20: 12.368896 | I20: =I19+1/12 -> 1871.875 | J20: =J10*2/12+J22*10/12 -> 5.3533333 | K20: =E20*$H$1851/H20 -> 117.96481 | L20: =F20*$H$1851/H20 -> 6.6100969 | M20: =M19*((K20+(L20/12))/K19) -> 123.50608 | N20: =G20*$H$1851/H20 -> 10.16938 | O20: =N20*(M20/K20) -> 10.647076 | P20: NA | R20: NA | U20: =((J20/J21+J20/1200+((1+J21/1200)^(-119))*(1-J20/J21))) -> 1.0042051 | V20: =V19*U19*H19/H20 -> 1.0507173 | W20: =(($M140/$M20)^(1/10)-1) -> 0.11526992 | X20: =(($V140/$V20)^(1/10)-1) -> 0.08259325 | Y20: =W20-X20 -> 0.032676669
A21: 1871.12 | B21: =VALUE(LEFT(A21, 4)) -> 1871 | C21: 12 | D21: =DATE(B21, VALUE(C21), 1) -> 683705 | E21: 4.74 | F21: 0.26 | G21: 0.4 | H21: 12.654392 | I21: =I20+1/12 -> 1871.9583 | J21: =J10*1/12+J22*11/12 -> 5.3566667 | K21: =E21*$H$1851/H21 -> 117.78839 | L21: =F21*$H$1851/H21 -> 6.4609664 | M21: =M20*((K21+(L21/12))/K20) -> 123.88508 | N21: =G21*$H$1851/H21 -> 9.9399483 | O21: =N21*(M21/K21) -> 10.454437 | P21: NA | R21: NA | U21: =((J21/J22+J21/1200+((1+J22/1200)^(-119))*(1-J21/J22))) -> 1.0042079 | V21: =V20*U20*H20/H21 -> 1.0313307 | W21: =(($M141/$M21)^(1/10)-1) -> 0.11213517 | X21: =(($V141/$V21)^(1/10)-1) -> 0.084999178 | Y21: =W21-X21 -> 0.027135996
A22: 1872.01 | B22: =VALUE(LEFT(A22, 4)) -> 1872 | C22: 1 | D22: =DATE(B22, VALUE(C22), 1) -> 683736 | E22: 4.86 | F22: 0.2633 | G22: 0.4025 | H22: 12.654392 | I22: =I21+1/12 -> 1872.0417 | J22: 5.36 | K22: =E22*$H$1851/H22 -> 120.77037 | L22: =F22*$H$1851/H22 -> 6.542971 | M22: =M21*((K22+(L22/12))/K21) -> 127.59488 | N22: =G22*$H$1851/H22 -> 10.002073 | O22: =N22*(M22/K22) -> 10.567271 | P22: NA | R22: NA | U22: =((J22/J23+J22/1200+((1+J23/1200)^(-119))*(1-J22/J23))) -> 1.00306 | V22: =V21*U21*H21/H22 -> 1.0356705 | W22: =(($M142/$M22)^(1/10)-1) -> 0.10768446 | X22: =(($V142/$V22)^(1/10)-1) -> 0.084930989 | Y22: =W22-X22 -> 0.022753475
A23: 1872.02 | B23: =VALUE(LEFT(A23, 4)) -> 1872 | C23: 2 | D23: =DATE(B23, VALUE(C23), 1) -> 683767 | E23: 4.88 | F23: 0.2667 | G23: 0.405 | H23: 12.654392 | I23: =I22+1/12 -> 1872.125 | J23: =J22*11/12+J34*1/12 -> 5.3783333 | K23: =E23*$H$1851/H23 -> 121.26737 | L23: =F23*$H$1851/H23 -> 6.6274605 | M23: =M22*((K23+(L23/12))/K22) -> 128.70346 | N23: =G23*$H$1851/H23 -> 10.064198 | O23: =N23*(M23/K23) -> 10.681332 | P23: NA | R23: NA | U23: =((J23/J24+J23/1200+((1+J24/1200)^(-119))*(1-J23/J24))) -> 1.0030764 | V23: =V22*U22*H22/H23 -> 1.0388396 | W23: =(($M143/$M23)^(1/10)-1) -> 0.10375208 | X23: =(($V143/$V23)^(1/10)-1) -> 0.083909829 | Y23: =W23-X23 -> 0.019842247
A24: 1872.03 | B24: =VALUE(LEFT(A24, 4)) -> 1872 | C24: 3 | D24: =DATE(B24, VALUE(C24), 1) -> 683796 | E24: 5.04 | F24: 0.27 | G24: 0.4075 | H24: 12.844641 | I24: =I23+1/12 -> 1872.2083 | J24: =J22*10/12+J34*2/12 -> 5.3966667 | K24: =E24*$H$1851/H24 -> 123.3883 | L24: =F24*$H$1851/H24 -> 6.6100873 | M24: =M23*((K24+(L24/12))/K23) -> 131.53906 | N24: =G24*$H$1851/H24 -> 9.9763354 | O24: =N24*(M24/K24) -> 10.63535 | P24: NA | R24: NA | U24: =((J24/J25+J24/1200+((1+J25/1200)^(-119))*(1-J24/J25))) -> 1.0030929 | V24: =V23*U23*H23/H24 -> 1.0266014 | W24: =(($M144/$M24)^(1/10)-1) -> 0.10166592 | X24: =(($V144/$V24)^(1/10)-1) -> 0.085514588 | Y24: =W24-X24 -> 0.016151334
A25: 1872.04 | B25: =VALUE(LEFT(A25, 4)) -> 1872 | C25: 4 | D25: =DATE(B25, VALUE(C25), 1) -> 683827 | E25: 5.18 | F25: 0.2733 | G25: 0.41 | H25: 13.130137 | I25: =I24+1/12 -> 1872.2917 | J25: =J22*9/12+J34*3/12 -> 5.415 | K25: =E25*$H$1851/H25 -> 124.05832 | L25: =F25*$H$1851/H25 -> 6.5453938 | M25: =M24*((K25+(L25/12))/K24) -> 132.83482 | N25: =G25*$H$1851/H25 -> 9.8192881 | O25: =N25*(M25/K25) -> 10.513953 | P25: NA | R25: NA | U25: =((J25/J26+J25/1200+((1+J26/1200)^(-119))*(1-J25/J26))) -> 1.0031093 | V25: =V24*U24*H24/H25 -> 1.0073855 | W25: =(($M145/$M25)^(1/10)-1) -> 0.10007867 | X25: =(($V145/$V25)^(1/10)-1) -> 0.086885498 | Y25: =W25-X25 -> 0.01319317
A26: 1872.05 | B26: =VALUE(LEFT(A26, 4)) -> 1872 | C26: 5 | D26: =DATE(B26, VALUE(C26), 1) -> 683857 | E26: 5.18 | F26: 0.2767 | G26: 0.4125 | H26: 13.130137 | I26: =I25+1/12 -> 1872.375 | J26: =J22*8/12+J34*4/12 -> 5.4333333 | K26: =E26*$H$1851/H26 -> 124.05832 | L26: =F26*$H$1851/H26 -> 6.626822 | M26: =M25*((K26+(L26/12))/K25) -> 133.42613 | N26: =G26*$H$1851/H26 -> 9.8791618 | O26: =N26*(M26/K26) -> 10.62515 | P26: NA | R26: NA | U26: =((J26/J27+J26/1200+((1+J27/1200)^(-119))*(1-J26/J27))) -> 1.0031258 | V26: =V25*U25*H25/H26 -> 1.0105178 | W26: =(($M146/$M26)^(1/10)-1) -> 0.097760664 | X26: =(($V146/$V26)^(1/10)-1) -> 0.085876681 | Y26: =W26-X26 -> 0.011883983
A27: 1872.06 | B27: =VALUE(LEFT(A27, 4)) -> 1872 | C27: 6 | D27: =DATE(B27, VALUE(C27), 1) -> 683888 | E27: 5.13 | F27: 0.28 | G27: 0.415 | H27: 13.034972 | I27: =I26+1/12 -> 1872.4583 | J27: =J22*7/12+J34*5/12 -> 5.4516667 | K27: =E27*$H$1851/H27 -> 123.75783 | L27: =F27*$H$1851/H27 -> 6.7548132 | M27: =M26*((K27+(L27/12))/K26) -> 133.70835 | N27: =G27*$H$1851/H27 -> 10.011598 | O27: =N27*(M27/K27) -> 10.816562 | P27: NA | R27: NA | U27: =((J27/J28+J27/1200+((1+J28/1200)^(-119))*(1-J27/J28))) -> 1.0031422 | V27: =V26*U26*H26/H27 -> 1.0210771 | W27: =(($M147/$M27)^(1/10)-1) -> 0.096471706 | X27: =(($V147/$V27)^(1/10)-1) -> 0.084086342 | Y27: =W27-X27 -> 0.012385364
A28: 1872.07 | B28: =VALUE(LEFT(A28, 4)) -> 1872 | C28: 7 | D28: =DATE(B28, VALUE(C28), 1) -> 683918 | E28: 5.1 | F28: 0.2833 | G28: 0.4175 | H28: 12.844641 | I28: =I27+1/12 -> 1872.5417 | J28: =J22*6/12+J34*6/12 -> 5.47 | K28: =E28*$H$1851/H28 -> 124.8572 | L28: =F28*$H$1851/H28 -> 6.9356953 | M28: =M27*((K28+(L28/12))/K27) -> 135.52056 | N28: =G28*$H$1851/H28 -> 10.221153 | O28: =N28*(M28/K28) -> 11.094085 | P28: NA | R28: NA | U28: =((J28/J29+J28/1200+((1+J29/1200)^(-119))*(1-J28/J29))) -> 1.0031587 | V28: =V27*U27*H27/H28 -> 1.0394633 | W28: =(($M148/$M28)^(1/10)-1) -> 0.1025004 | X28: =(($V148/$V28)^(1/10)-1) -> 0.083452521 | Y28: =W28-X28 -> 0.019047881
A29: 1872.08 | B29: =VALUE(LEFT(A29, 4)) -> 1872 | C29: 8 | D29: =DATE(B29, VALUE(C29), 1) -> 683949 | E29: 5.04 | F29: 0.2867 | G29: 0.42 | H29: 12.939807 | I29: =I28+1/12 -> 1872.625 | J29: =J22*5/12+J34*7/12 -> 5.4883333 | K29: =E29*$H$1851/H29 -> 122.48084 | L29: =F29*$H$1851/H29 -> 6.9673129 | M29: =M28*((K29+(L29/12))/K28) -> 133.57144 | N29: =G29*$H$1851/H29 -> 10.206737 | O29: =N29*(M29/K29) -> 11.130954 | P29: NA | R29: NA | U29: =((J29/J30+J29/1200+((1+J30/1200)^(-119))*(1-J29/J30))) -> 1.0031751 | V29: =V28*U28*H28/H29 -> 1.0350778 | W29: =(($M149/$M29)^(1/10)-1) -> 0.10684172 | X29: =(($V149/$V29)^(1/10)-1) -> 0.083249218 | Y29: =W29-X29 -> 0.0235925
A30: 1872.09 | B30: =VALUE(LEFT(A30, 4)) -> 1872 | C30: 9 | D30: =DATE(B30, VALUE(C30), 1) -> 683980 | E30: 4.95 | F30: 0.29 | G30: 0.4225 | H30: 13.034972 | I30: =I29+1/12 -> 1872.7083 | J30: =J22*4/12+J34*8/12 -> 5.5066667 | K30: =E30*$H$1851/H30 -> 119.41545 | L30: =F30*$H$1851/H30 -> 6.9960565 | M30: =M29*((K30+(L30/12))/K29) -> 130.86428 | N30: =G30*$H$1851/H30 -> 10.192531 | O30: =N30*(M30/K30) -> 11.169729 | P30: NA | R30: NA | U30: =((J30/J31+J30/1200+((1+J31/1200)^(-119))*(1-J30/J31))) -> 1.0031915 | V30: =V29*U29*H29/H30 -> 1.0307834 | W30: =(($M150/$M30)^(1/10)-1) -> 0.11370306 | X30: =(($V150/$V30)^(1/10)-1) -> 0.086993117 | Y30: =W30-X30 -> 0.026709944
A31: 1872.1 | B31: =VALUE(LEFT(A31, 4)) -> 1872 | C31: 10 | D31: =DATE(B31, VALUE(C31), 1) -> 684010 | E31: 4.97 | F31: 0.2933 | G31: 0.425 | H31: 12.749476 | I31: =I30+1/12 -> 1872.7917 | J31: =J22*3/12+J34*9/12 -> 5.525 | K31: =E31*$H$1851/H31 -> 122.58278 | L31: =F31*$H$1851/H31 -> 7.2341105 | M31: =M30*((K31+(L31/12))/K30) -> 134.99591 | N31: =G31*$H$1851/H31 -> 10.482431 | O31: =N31*(M31/K31) -> 11.543916 | P31: NA | R31: NA | U31: =((J31/J32+J31/1200+((1+J32/1200)^(-119))*(1-J31/J32))) -> 1.003208 | V31: =V30*U30*H30/H31 -> 1.057229 | W31: =(($M151/$M31)^(1/10)-1) -> 0.10870072 | X31: =(($V151/$V31)^(1/10)-1) -> 0.085572333 | Y31: =W31-X31 -> 0.023128387
A32: 1872.11 | B32: =VALUE(LEFT(A32, 4)) -> 1872 | C32: 11 | D32: =DATE(B32, VALUE(C32), 1) -> 684041 | E32: 4.95 | F32: 0.2967 | G32: 0.4275 | H32: 13.130137 | I32: =I31+1/12 -> 1872.875 | J32: =J22*2/12+J34*10/12 -> 5.5433333 | K32: =E32*$H$1851/H32 -> 118.54994 | L32: =F32*$H$1851/H32 -> 7.1058117 | M32: =M31*((K32+(L32/12))/K31) -> 131.20681 | N32: =G32*$H$1851/H32 -> 10.238404 | O32: =N32*(M32/K32) -> 11.331497 | P32: NA | R32: NA | U32: =((J32/J33+J32/1200+((1+J33/1200)^(-119))*(1-J32/J33))) -> 1.0032244 | V32: =V31*U31*H31/H32 -> 1.0298717 | W32: =(($M152/$M32)^(1/10)-1) -> 0.10855246 | X32: =(($V152/$V32)^(1/10)-1) -> 0.089766168 | Y32: =W32-X32 -> 0.01878629
A33: 1872.12 | B33: =VALUE(LEFT(A33, 4)) -> 1872 | C33: 12 | D33: =DATE(B33, VALUE(C33), 1) -> 684071 | E33: 5.07 | F33: 0.3 | G33: 0.43 | H33: 12.939807 | I33: =I32+1/12 -> 1872.9583 | J33: =J22*1/12+J34*11/12 -> 5.5616667 | K33: =E33*$H$1851/H33 -> 123.20989 | L33: =F33*$H$1851/H33 -> 7.2905263 | M33: =M32*((K33+(L33/12))/K32) -> 137.03668 | N33: =G33*$H$1851/H33 -> 10.449754 | O33: =N33*(M33/K33) -> 11.622441 | P33: NA | R33: NA | U33: =((J33/J34+J33/1200+((1+J34/1200)^(-119))*(1-J33/J34))) -> 1.0032409 | V33: =V32*U32*H32/H33 -> 1.0483896 | W33: =(($M153/$M33)^(1/10)-1) -> 0.10586247 | X33: =(($V153/$V33)^(1/10)-1) -> 0.08917802 | Y33: =W33-X33 -> 0.016684455
A34: 1873.01 | B34: =VALUE(LEFT(A34, 4)) -> 1873 | C34: 1 | D34: =DATE(B34, VALUE(C34), 1) -> 684102 | E34: 5.11 | F34: 0.3025 | G34: 0.4325 | H34: 12.939807 | I34: =I33+1/12 -> 1873.0417 | J34: 5.58 | K34: =E34*$H$1851/H34 -> 124.18196 | L34: =F34*$H$1851/H34 -> 7.3512807 | M34: =M33*((K34+(L34/12))/K33) -> 138.7992 | N34: =G34*$H$1851/H34 -> 10.510509 | O34: =N34*(M34/K34) -> 11.747681 | P34: NA | R34: NA | U34: =((J34/J35+J34/1200+((1+J35/1200)^(-119))*(1-J34/J35))) -> 1.0053472 | V34: =V33*U33*H33/H34 -> 1.0517872 | W34: =(($M154/$M34)^(1/10)-1) -> 0.10438834 | X34: =(($V154/$V34)^(1/10)-1) -> 0.089146981 | Y34: =W34-X34 -> 0.015241355
A35: 1873.02 | B35: =VALUE(LEFT(A35, 4)) -> 1873 | C35: 2 | D35: =DATE(B35, VALUE(C35), 1) -> 684133 | E35: 5.15 | F35: 0.305 | G35: 0.435 | H35: 13.225221 | I35: =I34+1/12 -> 1873.125 | J35: =J34*11/12+J46*1/12 -> 5.5708333 | K35: =E35*$H$1851/H35 -> 122.45307 | L35: =F35*$H$1851/H35 -> 7.2520751 | M35: =M34*((K35+(L35/12))/K34) -> 137.54227 | N35: =G35*$H$1851/H35 -> 10.343124 | O35: =N35*(M35/K35) -> 11.617648 | P35: NA | R35: NA | U35: =((J35/J36+J35/1200+((1+J36/1200)^(-119))*(1-J35/J36))) -> 1.0053399 | V35: =V34*U34*H34/H35 -> 1.0345913 | W35: =(($M155/$M35)^(1/10)-1) -> 0.10236955 | X35: =(($V155/$V35)^(1/10)-1) -> 0.090247719 | Y35: =W35-X35 -> 0.012121836
A36: 1873.03 | B36: =VALUE(LEFT(A36, 4)) -> 1873 | C36: 3 | D36: =DATE(B36, VALUE(C36), 1) -> 684161 | E36: 5.11 | F36: 0.3075 | G36: 0.4375 | H36: 13.225221 | I36: =I35+1/12 -> 1873.2083 | J36: =J34*10/12+J46*2/12 -> 5.5616667 | K36: =E36*$H$1851/H36 -> 121.50198 | L36: =F36*$H$1851/H36 -> 7.3115184 | M36: =M35*((K36+(L36/12))/K35) -> 137.15836 | N36: =G36*$H$1851/H36 -> 10.402567 | O36: =N36*(M36/K36) -> 11.74301 | P36: NA | R36: NA | U36: =((J36/J37+J36/1200+((1+J37/1200)^(-119))*(1-J36/J37))) -> 1.0053325 | V36: =V35*U35*H35/H36 -> 1.0401159 | W36: =(($M156/$M36)^(1/10)-1) -> 0.1055909 | X36: =(($V156/$V36)^(1/10)-1) -> 0.091036887 | Y36: =W36-X36 -> 0.014554018
A37: 1873.04 | B37: =VALUE(LEFT(A37, 4)) -> 1873 | C37: 4 | D37: =DATE(B37, VALUE(C37), 1) -> 684192 | E37: 5.04 | F37: 0.31 | G37: 0.44 | H37: 13.225221 | I37: =I36+1/12 -> 1873.2917 | J37: =J34*9/12+J46*3/12 -> 5.5525 | K37: =E37*$H$1851/H37 -> 119.83757 | L37: =F37*$H$1851/H37 -> 7.3709616 | M37: =M36*((K37+(L37/12))/K36) -> 135.97287 | N37: =G37*$H$1851/H37 -> 10.46201 | O37: =N37*(M37/K37) -> 11.870648 | P37: NA | R37: NA | U37: =((J37/J38+J37/1200+((1+J38/1200)^(-119))*(1-J37/J38))) -> 1.0053252 | V37: =V36*U36*H36/H37 -> 1.0456623 | W37: =(($M157/$M37)^(1/10)-1) -> 0.11040916 | X37: =(($V157/$V37)^(1/10)-1) -> 0.091838133 | Y37: =W37-X37 -> 0.01857103
A38: 1873.05 | B38: =VALUE(LEFT(A38, 4)) -> 1873 | C38: 5 | D38: =DATE(B38, VALUE(C38), 1) -> 684222 | E38: 5.05 | F38: 0.3125 | G38: 0.4425 | H38: 12.939807 | I38: =I37+1/12 -> 1873.375 | J38: =J34*8/12+J46*4/12 -> 5.5433333 | K38: =E38*$H$1851/H38 -> 122.72386 | L38: =F38*$H$1851/H38 -> 7.5942982 | M38: =M37*((K38+(L38/12))/K37) -> 139.96585 | N38: =G38*$H$1851/H38 -> 10.753526 | O38: =N38*(M38/K38) -> 12.264334 | P38: NA | R38: NA | U38: =((J38/J39+J38/1200+((1+J39/1200)^(-119))*(1-J38/J39))) -> 1.0053178 | V38: =V37*U37*H37/H38 -> 1.0744178 | W38: =(($M158/$M38)^(1/10)-1) -> 0.10688474 | X38: =(($V158/$V38)^(1/10)-1) -> 0.090269519 | Y38: =W38-X38 -> 0.016615217
A39: 1873.06 | B39: =VALUE(LEFT(A39, 4)) -> 1873 | C39: 6 | D39: =DATE(B39, VALUE(C39), 1) -> 684253 | E39: 4.98 | F39: 0.315 | G39: 0.445 | H39: 12.559226 | I39: =I38+1/12 -> 1873.4583 | J39: =J34*7/12+J46*5/12 -> 5.5341667 | K39: =E39*$H$1851/H39 -> 124.69007 | L39: =F39*$H$1851/H39 -> 7.8870224 | M39: =M38*((K39+(L39/12))/K38) -> 142.95789 | N39: =G39*$H$1851/H39 -> 11.141984 | O39: =N39*(M39/K39) -> 12.77435 | P39: NA | R39: NA | U39: =((J39/J40+J39/1200+((1+J40/1200)^(-119))*(1-J39/J40))) -> 1.0053105 | V39: =V38*U38*H38/H39 -> 1.1128624 | W39: =(($M159/$M39)^(1/10)-1) -> 0.10928659 | X39: =(($V159/$V39)^(1/10)-1) -> 0.089995543 | Y39: =W39-X39 -> 0.019291046
A40: 1873.07 | B40: =VALUE(LEFT(A40, 4)) -> 1873 | C40: 7 | D40: =DATE(B40, VALUE(C40), 1) -> 684283 | E40: 4.97 | F40: 0.3175 | G40: 0.4475 | H40: 12.559226 | I40: =I39+1/12 -> 1873.5417 | J40: =J34*6/12+J46*6/12 -> 5.525 | K40: =E40*$H$1851/H40 -> 124.43969 | L40: =F40*$H$1851/H40 -> 7.9496178 | M40: =M39*((K40+(L40/12))/K39) -> 143.43035 | N40: =G40*$H$1851/H40 -> 11.204579 | O40: =N40*(M40/K40) -> 12.914503 | P40: NA | R40: NA | U40: =((J40/J41+J40/1200+((1+J41/1200)^(-119))*(1-J40/J41))) -> 1.0053031 | V40: =V39*U39*H39/H40 -> 1.1187722 | W40: =(($M160/$M40)^(1/10)-1) -> 0.10995788 | X40: =(($V160/$V40)^(1/10)-1) -> 0.091958924 | Y40: =W40-X40 -> 0.017998957
A41: 1873.08 | B41: =VALUE(LEFT(A41, 4)) -> 1873 | C41: 8 | D41: =DATE(B41, VALUE(C41), 1) -> 684314 | E41: 4.97 | F41: 0.32 | G41: 0.45 | H41: 12.559226 | I41: =I40+1/12 -> 1873.625 | J41: =J34*5/12+J46*7/12 -> 5.5158333 | K41: =E41*$H$1851/H41 -> 124.43969 | L41: =F41*$H$1851/H41 -> 8.0122132 | M41: =M40*((K41+(L41/12))/K40) -> 144.19993 | N41: =G41*$H$1851/H41 -> 11.267175 | O41: =N41*(M41/K41) -> 13.056332 | P41: NA | R41: NA | U41: =((J41/J42+J41/1200+((1+J42/1200)^(-119))*(1-J41/J42))) -> 1.0052958 | V41: =V40*U40*H40/H41 -> 1.1247052 | W41: =(($M161/$M41)^(1/10)-1) -> 0.10477284 | X41: =(($V161/$V41)^(1/10)-1) -> 0.091718314 | Y41: =W41-X41 -> 0.013054527
...

Sheet ICSA
A1: Link: | B1: Initial Claims (Number)
A3: Date | B3: ICSA
A4: 24473 | B4: 209000
A5: 24504 | B5: 229000
A6: 24532 | B6: 260750
A7: 24563 | B7: 263000
A8: 24593 | B8: 235750
A9: 24624 | B9: 232000
A10: 24654 | B10: 227800
A11: 24685 | B11: 212750
A12: 24716 | B12: 216400
A13: 24746 | B13: 216750
A14: 24777 | B14: 206250
A15: 24807 | B15: 211200
... A693: 45444 | B693: 236600

Sheet IURSA
A1: Link: | B1: Insured Unemployment Rate (%)
A3: Date | B3: IURSA
A4: 25934 | B4: 3.92
A5: 25965 | B5: 3.95
A6: 25993 | B6: 4.025
A7: 26024 | B7: 4.05
A8: 26054 | B8: 4.1
A9: 26085 | B9: 4.1
A10: 26115 | B10: 4.02
A11: 26146 | B11: 4.125
A12: 26177 | B12: 4.25
A13: 26207 | B13: 4.2
A14: 26238 | B14: 4.1
A15: 26268 | B15: 3.975
... A645: 45444 | B645: 1.2

Sheet JTSJOL
A1: Link: | B1: Job Openings: Total Nonfarm (Level in Thousands)
A3: Date | B3: JTSJOL
A4: 36861 | B4: 5088
A5: 36892 | B5: 5234
A6: 36923 | B6: 5097
A7: 36951 | B7: 4762
A8: 36982 | B8: 4615
A9: 37012 | B9: 4425
A10: 37043 | B10: 4361
A11: 37073 | B11: 4447
A12: 37104 | B12: 4024
A13: 37135 | B13: 4071
A14: 37165 | B14: 3707
A15: 37196 | B15: 3775
... A285: 45413 | B285: 8140

Sheet PAYEMS
A1: Link: | B1: All Employees, Total Nonfarm (Thousands of Persons)
A3: Date | B3: PAYEMS
A4: 14246 | B4: 29923
A5: 14277 | B5: 30100
A6: 14305 | B6: 30280
A7: 14336 | B7: 30094
A8: 14366 | B8: 30299
A9: 14397 | B9: 30502
A10: 14427 | B10: 30419
A11: 14458 | B11: 30663
A12: 14489 | B12: 31031
A13: 14519 | B13: 31411
A14: 14550 | B14: 31470
A15: 14580 | B15: 31542
... A1029: 45444 | B1029: 158638

Sheet MANEMP
A1: Link: | B1: All Employees, Manufacturing (Thousands of Persons)
A3: Date | B3: MANEMP
A4: 14246 | B4: 9077
A5: 14277 | B5: 9175
A6: 14305 | B6: 9275
A7: 14336 | B7: 9309
A8: 14366 | B8: 9299
A9: 14397 | B9: 9315
A10: 14427 | B10: 9231
A11: 14458 | B11: 9400
A12: 14489 | B12: 9604
A13: 14519 | B13: 9873
A14: 14550 | B14: 9896
A15: 14580 | B15: 9949
... A1029: 45444 | B1029: 12950

Sheet UNRATE
A1: Link: | B1: Unemployment Rate (%)
A3: Date | B3: UNRATE
A4: 17533 | B4: 3.4
A5: 17564 | B5: 3.8
A6: 17593 | B6: 4
A7: 17624 | B7: 3.9
A8: 17654 | B8: 3.5
A9: 17685 | B9: 3.6
A10: 17715 | B10: 3.6
A11: 17746 | B11: 3.9
A12: 17777 | B12: 3.8
A13: 17807 | B13: 3.7
A14: 17838 | B14: 3.8
A15: 17868 | B15: 4
... A921: 45444 | B921: 4.1

Sheet IEAXGS
A1: Link: | B1: Exports of goods and services (Millions of Dollars)
A3: Date | B3: IEAXGS
A4: 36161 | B4: 235387
A5: 36251 | B5: 238878
A6: 36342 | B6: 247493
A7: 36434 | B7: 254767
A8: 36526 | B8: 260656
A9: 36617 | B9: 269952
A10: 36708 | B10: 277204
A11: 36800 | B11: 275151
A12: 36892 | B12: 271148
A13: 36982 | B13: 262318
A14: 37073 | B14: 246592
A15: 37165 | B15: 235308
... A104: 45292 | B104: 787178

Sheet IEAMGSN
A1: Link: | B1: Imports of goods and services (Millions of Dollars)
A3: Date | B3: IEAMGSN
A4: 36161 | B4: 275721
A5: 36251 | B5: 300975
A6: 36342 | B6: 323481
A7: 36434 | B7: 332158
A8: 36526 | B8: 335244
A9: 36617 | B9: 359940
A10: 36708 | B10: 380471
A11: 36800 | B11: 376995
A12: 36892 | B12: 353790
A13: 36982 | B13: 350895
A14: 37073 | B14: 342129
A15: 37165 | B15: 328926
... A104: 45292 | B104: 948773

Sheet GFDEGDQ188S
A1: Link: | B1: Federal Debt: Total Public Debt as Percent of Gross Domestic Product (%)
A3: Date | B3: GFDEGDQ188S
A4: 24108 | B4: 40.33999
A5: 24198 | B5: 39.26763
A6: 24289 | B6: 39.62091
A7: 24381 | B7: 39.51977
A8: 24473 | B8: 39.20383
A9: 24563 | B9: 38.03292
A10: 24654 | B10: 38.82145
A11: 24746 | B11: 39.10231
A12: 24838 | B12: 38.42951
A13: 24929 | B13: 36.96379
A14: 25020 | B14: 37.30897
A15: 25112 | B15: 36.98532
... A236: 45292 | B236: 122.34717
